Workbook

Sheet README
A1: PACK RESTAURANT OS - INSTALLATION ET UTILISATION
A3: 1. Remplir PREVISION_SERVICE avec les couverts prévus par date et service.
A4: 2. Remplir UTILISATEURS avec les PIN salariés.
A5: 3. Importer ce fichier dans Google Sheets.
A6: 4. Ouvrir Extensions > Apps Script, puis coller le contenu du fichier APPS_SCRIPT.gs du pack.
A7: 5. Déployer le script en Web App, accès : Toute personne disposant du lien.
A8: 6. Copier l'URL du Web App dans public/config.js à la ligne APPS_SCRIPT_URL.
A9: 7. Mettre le dossier public en ligne (GitHub Pages, Netlify, etc.).
A10: 8. Installer sur iOS via Safari > Partager > Ajouter à l'écran d'accueil.
A11: 9. Installer sur Android via Chrome > Ajouter à l'écran d'accueil.
A12: 10. Utiliser les formulaires Ruptures et Pertes pour alimenter automatiquement COMMANDE_AUTO.
A15: Fonctionnalités incluses :
... A19: - V4 : Pertes de produits déjà préparés

Sheet UTILISATEURS
A1: Actif | B1: Nom | C1: Rôle | D1: PIN | E1: Email validation | F1: Peut valider | G1: Peut voir admin
A2: Oui | B2: Christelle | C2: Cuisine | D2: 1111 | E2: johndrelin@gmail.com | F2: Oui | G2: Non
A3: Oui | B3: Ludovic | C3: Chef | D3: 2222 | E3: johndrelin@gmail.com | F3: Oui | G3: Non
A4: Oui | B4: Lesli | C4: Support | D4: 3333 | E4: johndrelin@gmail.com | F4: Oui | G4: Non
A5: Oui | B5: Admin | C5: Admin | D5: 9999 | E5: johndrelin@gmail.com | F5: Oui | G5: Oui

Sheet PARAMETRES
A1: Clé | B1: Valeur | C1: Commentaire
A2: Nom_restaurant | B2: L'Embouchure | C2: Nom affiché dans l'app
A3: Email_manager | B3: johndrelin@gmail.com | C3: Réception des validations
A4: Heure_debut_midi | B4: 08:00 | C4: Détection automatique
A5: Heure_fin_midi | B5: 15:00 | C5: Détection automatique
A6: Heure_debut_soir | B6: 15:01 | C6: Détection automatique
A7: Heure_fin_soir | B7: 23:59 | C7: Détection automatique
A8: Lissage_analyse | B8: 0.5 | C8: Poids de l'ancien ratio (0.50 = 50%)

Sheet PREVISION_SERVICE
A1: Date | B1: Jour | C1: Service | D1: Couverts | E1: Observations
A2: 2026-03-30 | B2: Lundi | C2: Midi | D2: 18
A3: 2026-03-31 | B3: Mardi | C3: Midi | D3: 18
A4: 2026-03-31 | B4: Mardi | C4: Soir | D4: 20
A5: 2026-04-01 | B5: Mercredi | C5: Midi | D5: 18
A6: 2026-04-01 | B6: Mercredi | C6: Soir | D6: 20
A7: 2026-04-02 | B7: Jeudi | C7: Soir | D7: 28 | E7: Affluence forte
A8: 2026-04-03 | B8: Vendredi | C8: Midi | D8: 25
A9: 2026-04-03 | B9: Vendredi | C9: Soir | D9: 30 | E9: Affluence forte
A10: 2026-04-04 | B10: Samedi | C10: Soir | D10: 30 | E10: Affluence forte
A11: 2026-04-05 | B11: Dimanche | C11: Midi | D11: 20

Sheet RATIOS_INITIAUX
A1: Plat | B1: Type | C1: Unité | D1: Ratio par couvert | E1: Commentaire
A2: Accras | B2: Entrée | C2: portion | D2: 0.4 | E2: portion moyenne par couvert
A3: Nems | B3: Entrée | C3: portion | D3: 0.18
A4: Samoussas | B4: Entrée | C4: portion | D4: 0.18
A5: Crevettes tempura | B5: Entrée | C5: portion | D5: 0.12
A6: Pisquettes | B6: Entrée | C6: portion | D6: 0.1
A7: Tapas trio | B7: Entrée | C7: portion | D7: 0.08
A8: Assiette créole | B8: Entrée | C8: portion | D8: 0.1
A9: Salade Cap Est | B9: Plat | C9: portion | D9: 0.2
A10: Brochette de boeuf | B10: Plat | C10: portion | D10: 0.1
A11: Brochette de crevettes | B11: Plat | C11: portion | D11: 0.1
A12: Brochette de poisson | B12: Plat | C12: portion | D12: 0.1
A13: Brochette de poulet | B13: Plat | C13: portion | D13: 0.16
A14: Brochette de légumes | B14: Plat | C14: portion | D14: 0.06
... A30: Boule de glace | B30: Dessert | C30: portion | D30: 0.18

Sheet VENTES_REELLES
A1: Date | B1: Service | C1: Plat | D1: Quantité vendue | E1: Observations

Sheet ANALYSE
A1: Plat | B1: Ratio initial | C1: Ventes réelles totales | D1: Couverts totaux | E1: Ratio réel | F1: Nouveau ratio recommandé
A2: Accras | B2: =IFERROR(VLOOKUP(A2,RATIOS_INITIAUX!A:D,4,FALSE),0) | C2: =SUMIF(VENTES_REELLES!C:C,A2,VENTES_REELLES!D:D) | D2: =SUM(PREVISION_SERVICE!D:D) | E2: =IFERROR(C2/D2,0) | F2: =ROUND((B2*PARAMETRES!B7)+(E2*(1-PARAMETRES!B7)),3)
A3: Nems | B3: =IFERROR(VLOOKUP(A3,RATIOS_INITIAUX!A:D,4,FALSE),0) | C3: =SUMIF(VENTES_REELLES!C:C,A3,VENTES_REELLES!D:D) | D3: =SUM(PREVISION_SERVICE!D:D) | E3: =IFERROR(C3/D3,0) | F3: =ROUND((B3*PARAMETRES!B7)+(E3*(1-PARAMETRES!B7)),3)
A4: Samoussas | B4: =IFERROR(VLOOKUP(A4,RATIOS_INITIAUX!A:D,4,FALSE),0) | C4: =SUMIF(VENTES_REELLES!C:C,A4,VENTES_REELLES!D:D) | D4: =SUM(PREVISION_SERVICE!D:D) | E4: =IFERROR(C4/D4,0) | F4: =ROUND((B4*PARAMETRES!B7)+(E4*(1-PARAMETRES!B7)),3)
A5: Crevettes tempura | B5: =IFERROR(VLOOKUP(A5,RATIOS_INITIAUX!A:D,4,FALSE),0) | C5: =SUMIF(VENTES_REELLES!C:C,A5,VENTES_REELLES!D:D) | D5: =SUM(PREVISION_SERVICE!D:D) | E5: =IFERROR(C5/D5,0) | F5: =ROUND((B5*PARAMETRES!B7)+(E5*(1-PARAMETRES!B7)),3)
A6: Pisquettes | B6: =IFERROR(VLOOKUP(A6,RATIOS_INITIAUX!A:D,4,FALSE),0) | C6: =SUMIF(VENTES_REELLES!C:C,A6,VENTES_REELLES!D:D) | D6: =SUM(PREVISION_SERVICE!D:D) | E6: =IFERROR(C6/D6,0) | F6: =ROUND((B6*PARAMETRES!B7)+(E6*(1-PARAMETRES!B7)),3)
A7: Tapas trio | B7: =IFERROR(VLOOKUP(A7,RATIOS_INITIAUX!A:D,4,FALSE),0) | C7: =SUMIF(VENTES_REELLES!C:C,A7,VENTES_REELLES!D:D) | D7: =SUM(PREVISION_SERVICE!D:D) | E7: =IFERROR(C7/D7,0) | F7: =ROUND((B7*PARAMETRES!B7)+(E7*(1-PARAMETRES!B7)),3)
A8: Assiette créole | B8: =IFERROR(VLOOKUP(A8,RATIOS_INITIAUX!A:D,4,FALSE),0) | C8: =SUMIF(VENTES_REELLES!C:C,A8,VENTES_REELLES!D:D) | D8: =SUM(PREVISION_SERVICE!D:D) | E8: =IFERROR(C8/D8,0) | F8: =ROUND((B8*PARAMETRES!B7)+(E8*(1-PARAMETRES!B7)),3)
A9: Salade Cap Est | B9: =IFERROR(VLOOKUP(A9,RATIOS_INITIAUX!A:D,4,FALSE),0) | C9: =SUMIF(VENTES_REELLES!C:C,A9,VENTES_REELLES!D:D) | D9: =SUM(PREVISION_SERVICE!D:D) | E9: =IFERROR(C9/D9,0) | F9: =ROUND((B9*PARAMETRES!B7)+(E9*(1-PARAMETRES!B7)),3)
A10: Brochette de boeuf | B10: =IFERROR(VLOOKUP(A10,RATIOS_INITIAUX!A:D,4,FALSE),0) | C10: =SUMIF(VENTES_REELLES!C:C,A10,VENTES_REELLES!D:D) | D10: =SUM(PREVISION_SERVICE!D:D) | E10: =IFERROR(C10/D10,0) | F10: =ROUND((B10*PARAMETRES!B7)+(E10*(1-PARAMETRES!B7)),3)
A11: Brochette de crevettes | B11: =IFERROR(VLOOKUP(A11,RATIOS_INITIAUX!A:D,4,FALSE),0) | C11: =SUMIF(VENTES_REELLES!C:C,A11,VENTES_REELLES!D:D) | D11: =SUM(PREVISION_SERVICE!D:D) | E11: =IFERROR(C11/D11,0) | F11: =ROUND((B11*PARAMETRES!B7)+(E11*(1-PARAMETRES!B7)),3)
A12: Brochette de poisson | B12: =IFERROR(VLOOKUP(A12,RATIOS_INITIAUX!A:D,4,FALSE),0) | C12: =SUMIF(VENTES_REELLES!C:C,A12,VENTES_REELLES!D:D) | D12: =SUM(PREVISION_SERVICE!D:D) | E12: =IFERROR(C12/D12,0) | F12: =ROUND((B12*PARAMETRES!B7)+(E12*(1-PARAMETRES!B7)),3)
A13: Brochette de poulet | B13: =IFERROR(VLOOKUP(A13,RATIOS_INITIAUX!A:D,4,FALSE),0) | C13: =SUMIF(VENTES_REELLES!C:C,A13,VENTES_REELLES!D:D) | D13: =SUM(PREVISION_SERVICE!D:D) | E13: =IFERROR(C13/D13,0) | F13: =ROUND((B13*PARAMETRES!B7)+(E13*(1-PARAMETRES!B7)),3)
A14: Brochette de légumes | B14: =IFERROR(VLOOKUP(A14,RATIOS_INITIAUX!A:D,4,FALSE),0) | C14: =SUMIF(VENTES_REELLES!C:C,A14,VENTES_REELLES!D:D) | D14: =SUM(PREVISION_SERVICE!D:D) | E14: =IFERROR(C14/D14,0) | F14: =ROUND((B14*PARAMETRES!B7)+(E14*(1-PARAMETRES!B7)),3)
A15: Entrecôte | B15: =IFERROR(VLOOKUP(A15,RATIOS_INITIAUX!A:D,4,FALSE),0) | C15: =SUMIF(VENTES_REELLES!C:C,A15,VENTES_REELLES!D:D) | D15: =SUM(PREVISION_SERVICE!D:D) | E15: =IFERROR(C15/D15,0) | F15: =ROUND((B15*PARAMETRES!B7)+(E15*(1-PARAMETRES!B7)),3)
A16: Pièce du boucher | B16: =IFERROR(VLOOKUP(A16,RATIOS_INITIAUX!A:D,4,FALSE),0) | C16: =SUMIF(VENTES_REELLES!C:C,A16,VENTES_REELLES!D:D) | D16: =SUM(PREVISION_SERVICE!D:D) | E16: =IFERROR(C16/D16,0) | F16: =ROUND((B16*PARAMETRES!B7)+(E16*(1-PARAMETRES!B7)),3)
A17: Magret de canard | B17: =IFERROR(VLOOKUP(A17,RATIOS_INITIAUX!A:D,4,FALSE),0) | C17: =SUMIF(VENTES_REELLES!C:C,A17,VENTES_REELLES!D:D) | D17: =SUM(PREVISION_SERVICE!D:D) | E17: =IFERROR(C17/D17,0) | F17: =ROUND((B17*PARAMETRES!B7)+(E17*(1-PARAMETRES!B7)),3)
A18: Côte de boeuf | B18: =IFERROR(VLOOKUP(A18,RATIOS_INITIAUX!A:D,4,FALSE),0) | C18: =SUMIF(VENTES_REELLES!C:C,A18,VENTES_REELLES!D:D) | D18: =SUM(PREVISION_SERVICE!D:D) | E18: =IFERROR(C18/D18,0) | F18: =ROUND((B18*PARAMETRES!B7)+(E18*(1-PARAMETRES!B7)),3)
A19: Filet de poisson frais | B19: =IFERROR(VLOOKUP(A19,RATIOS_INITIAUX!A:D,4,FALSE),0) | C19: =SUMIF(VENTES_REELLES!C:C,A19,VENTES_REELLES!D:D) | D19: =SUM(PREVISION_SERVICE!D:D) | E19: =IFERROR(C19/D19,0) | F19: =ROUND((B19*PARAMETRES!B7)+(E19*(1-PARAMETRES!B7)),3)
A20: Tartare de poisson | B20: =IFERROR(VLOOKUP(A20,RATIOS_INITIAUX!A:D,4,FALSE),0) | C20: =SUMIF(VENTES_REELLES!C:C,A20,VENTES_REELLES!D:D) | D20: =SUM(PREVISION_SERVICE!D:D) | E20: =IFERROR(C20/D20,0) | F20: =ROUND((B20*PARAMETRES!B7)+(E20*(1-PARAMETRES!B7)),3)
A21: Frites maison | B21: =IFERROR(VLOOKUP(A21,RATIOS_INITIAUX!A:D,4,FALSE),0) | C21: =SUMIF(VENTES_REELLES!C:C,A21,VENTES_REELLES!D:D) | D21: =SUM(PREVISION_SERVICE!D:D) | E21: =IFERROR(C21/D21,0) | F21: =ROUND((B21*PARAMETRES!B7)+(E21*(1-PARAMETRES!B7)),3)
A22: Salade | B22: =IFERROR(VLOOKUP(A22,RATIOS_INITIAUX!A:D,4,FALSE),0) | C22: =SUMIF(VENTES_REELLES!C:C,A22,VENTES_REELLES!D:D) | D22: =SUM(PREVISION_SERVICE!D:D) | E22: =IFERROR(C22/D22,0) | F22: =ROUND((B22*PARAMETRES!B7)+(E22*(1-PARAMETRES!B7)),3)
A23: Légumes variés | B23: =IFERROR(VLOOKUP(A23,RATIOS_INITIAUX!A:D,4,FALSE),0) | C23: =SUMIF(VENTES_REELLES!C:C,A23,VENTES_REELLES!D:D) | D23: =SUM(PREVISION_SERVICE!D:D) | E23: =IFERROR(C23/D23,0) | F23: =ROUND((B23*PARAMETRES!B7)+(E23*(1-PARAMETRES!B7)),3)
A24: Gratin | B24: =IFERROR(VLOOKUP(A24,RATIOS_INITIAUX!A:D,4,FALSE),0) | C24: =SUMIF(VENTES_REELLES!C:C,A24,VENTES_REELLES!D:D) | D24: =SUM(PREVISION_SERVICE!D:D) | E24: =IFERROR(C24/D24,0) | F24: =ROUND((B24*PARAMETRES!B7)+(E24*(1-PARAMETRES!B7)),3)
A25: Fondant chocolat | B25: =IFERROR(VLOOKUP(A25,RATIOS_INITIAUX!A:D,4,FALSE),0) | C25: =SUMIF(VENTES_REELLES!C:C,A25,VENTES_REELLES!D:D) | D25: =SUM(PREVISION_SERVICE!D:D) | E25: =IFERROR(C25/D25,0) | F25: =ROUND((B25*PARAMETRES!B7)+(E25*(1-PARAMETRES!B7)),3)
A26: Tartelettes | B26: =IFERROR(VLOOKUP(A26,RATIOS_INITIAUX!A:D,4,FALSE),0) | C26: =SUMIF(VENTES_REELLES!C:C,A26,VENTES_REELLES!D:D) | D26: =SUM(PREVISION_SERVICE!D:D) | E26: =IFERROR(C26/D26,0) | F26: =ROUND((B26*PARAMETRES!B7)+(E26*(1-PARAMETRES!B7)),3)
A27: Profiteroles | B27: =IFERROR(VLOOKUP(A27,RATIOS_INITIAUX!A:D,4,FALSE),0) | C27: =SUMIF(VENTES_REELLES!C:C,A27,VENTES_REELLES!D:D) | D27: =SUM(PREVISION_SERVICE!D:D) | E27: =IFERROR(C27/D27,0) | F27: =ROUND((B27*PARAMETRES!B7)+(E27*(1-PARAMETRES!B7)),3)
A28: Gaufres | B28: =IFERROR(VLOOKUP(A28,RATIOS_INITIAUX!A:D,4,FALSE),0) | C28: =SUMIF(VENTES_REELLES!C:C,A28,VENTES_REELLES!D:D) | D28: =SUM(PREVISION_SERVICE!D:D) | E28: =IFERROR(C28/D28,0) | F28: =ROUND((B28*PARAMETRES!B7)+(E28*(1-PARAMETRES!B7)),3)
A29: Compotée | B29: =IFERROR(VLOOKUP(A29,RATIOS_INITIAUX!A:D,4,FALSE),0) | C29: =SUMIF(VENTES_REELLES!C:C,A29,VENTES_REELLES!D:D) | D29: =SUM(PREVISION_SERVICE!D:D) | E29: =IFERROR(C29/D29,0) | F29: =ROUND((B29*PARAMETRES!B7)+(E29*(1-PARAMETRES!B7)),3)
A30: Boule de glace | B30: =IFERROR(VLOOKUP(A30,RATIOS_INITIAUX!A:D,4,FALSE),0) | C30: =SUMIF(VENTES_REELLES!C:C,A30,VENTES_REELLES!D:D) | D30: =SUM(PREVISION_SERVICE!D:D) | E30: =IFERROR(C30/D30,0) | F30: =ROUND((B30*PARAMETRES!B7)+(E30*(1-PARAMETRES!B7)),3)

Sheet MISE_EN_PLACE
A1: Date | B1: Service | C1: Plat | D1: Ratio utilisé | E1: Quantité calculée | F1: Unité | G1: Assigné à
A2: =PREVISION_SERVICE!A2 | B2: =PREVISION_SERVICE!C2 | C2: Accras | D2: =IFERROR(VLOOKUP(C2,ANALYSE!A:F,6,FALSE),0) | E2: =ROUND(PREVISION_SERVICE!D2*D2,1) | F2: portion | G2: Christelle
A3: =PREVISION_SERVICE!A2 | B3: =PREVISION_SERVICE!C2 | C3: Nems | D3: =IFERROR(VLOOKUP(C3,ANALYSE!A:F,6,FALSE),0) | E3: =ROUND(PREVISION_SERVICE!D2*D3,1) | F3: portion | G3: Christelle
A4: =PREVISION_SERVICE!A2 | B4: =PREVISION_SERVICE!C2 | C4: Samoussas | D4: =IFERROR(VLOOKUP(C4,ANALYSE!A:F,6,FALSE),0) | E4: =ROUND(PREVISION_SERVICE!D2*D4,1) | F4: portion | G4: Christelle
A5: =PREVISION_SERVICE!A2 | B5: =PREVISION_SERVICE!C2 | C5: Crevettes tempura | D5: =IFERROR(VLOOKUP(C5,ANALYSE!A:F,6,FALSE),0) | E5: =ROUND(PREVISION_SERVICE!D2*D5,1) | F5: portion | G5: Christelle
A6: =PREVISION_SERVICE!A2 | B6: =PREVISION_SERVICE!C2 | C6: Pisquettes | D6: =IFERROR(VLOOKUP(C6,ANALYSE!A:F,6,FALSE),0) | E6: =ROUND(PREVISION_SERVICE!D2*D6,1) | F6: portion | G6: Christelle
A7: =PREVISION_SERVICE!A2 | B7: =PREVISION_SERVICE!C2 | C7: Tapas trio | D7: =IFERROR(VLOOKUP(C7,ANALYSE!A:F,6,FALSE),0) | E7: =ROUND(PREVISION_SERVICE!D2*D7,1) | F7: portion | G7: Christelle
A8: =PREVISION_SERVICE!A2 | B8: =PREVISION_SERVICE!C2 | C8: Assiette créole | D8: =IFERROR(VLOOKUP(C8,ANALYSE!A:F,6,FALSE),0) | E8: =ROUND(PREVISION_SERVICE!D2*D8,1) | F8: portion | G8: Christelle
A9: =PREVISION_SERVICE!A2 | B9: =PREVISION_SERVICE!C2 | C9: Salade Cap Est | D9: =IFERROR(VLOOKUP(C9,ANALYSE!A:F,6,FALSE),0) | E9: =ROUND(PREVISION_SERVICE!D2*D9,1) | F9: portion | G9: Christelle
A10: =PREVISION_SERVICE!A2 | B10: =PREVISION_SERVICE!C2 | C10: Brochette de boeuf | D10: =IFERROR(VLOOKUP(C10,ANALYSE!A:F,6,FALSE),0) | E10: =ROUND(PREVISION_SERVICE!D2*D10,1) | F10: portion | G10: Ludovic
A11: =PREVISION_SERVICE!A2 | B11: =PREVISION_SERVICE!C2 | C11: Brochette de crevettes | D11: =IFERROR(VLOOKUP(C11,ANALYSE!A:F,6,FALSE),0) | E11: =ROUND(PREVISION_SERVICE!D2*D11,1) | F11: portion | G11: Ludovic
A12: =PREVISION_SERVICE!A2 | B12: =PREVISION_SERVICE!C2 | C12: Brochette de poisson | D12: =IFERROR(VLOOKUP(C12,ANALYSE!A:F,6,FALSE),0) | E12: =ROUND(PREVISION_SERVICE!D2*D12,1) | F12: portion | G12: Ludovic
A13: =PREVISION_SERVICE!A2 | B13: =PREVISION_SERVICE!C2 | C13: Brochette de poulet | D13: =IFERROR(VLOOKUP(C13,ANALYSE!A:F,6,FALSE),0) | E13: =ROUND(PREVISION_SERVICE!D2*D13,1) | F13: portion | G13: Ludovic
A14: =PREVISION_SERVICE!A2 | B14: =PREVISION_SERVICE!C2 | C14: Brochette de légumes | D14: =IFERROR(VLOOKUP(C14,ANALYSE!A:F,6,FALSE),0) | E14: =ROUND(PREVISION_SERVICE!D2*D14,1) | F14: portion | G14: Ludovic
A15: =PREVISION_SERVICE!A2 | B15: =PREVISION_SERVICE!C2 | C15: Entrecôte | D15: =IFERROR(VLOOKUP(C15,ANALYSE!A:F,6,FALSE),0) | E15: =ROUND(PREVISION_SERVICE!D2*D15,1) | F15: portion | G15: Ludovic
A16: =PREVISION_SERVICE!A2 | B16: =PREVISION_SERVICE!C2 | C16: Pièce du boucher | D16: =IFERROR(VLOOKUP(C16,ANALYSE!A:F,6,FALSE),0) | E16: =ROUND(PREVISION_SERVICE!D2*D16,1) | F16: portion | G16: Ludovic
A17: =PREVISION_SERVICE!A2 | B17: =PREVISION_SERVICE!C2 | C17: Magret de canard | D17: =IFERROR(VLOOKUP(C17,ANALYSE!A:F,6,FALSE),0) | E17: =ROUND(PREVISION_SERVICE!D2*D17,1) | F17: portion | G17: Ludovic
A18: =PREVISION_SERVICE!A2 | B18: =PREVISION_SERVICE!C2 | C18: Côte de boeuf | D18: =IFERROR(VLOOKUP(C18,ANALYSE!A:F,6,FALSE),0) | E18: =ROUND(PREVISION_SERVICE!D2*D18,1) | F18: portion | G18: Ludovic
A19: =PREVISION_SERVICE!A2 | B19: =PREVISION_SERVICE!C2 | C19: Filet de poisson frais | D19: =IFERROR(VLOOKUP(C19,ANALYSE!A:F,6,FALSE),0) | E19: =ROUND(PREVISION_SERVICE!D2*D19,1) | F19: portion | G19: Ludovic
A20: =PREVISION_SERVICE!A2 | B20: =PREVISION_SERVICE!C2 | C20: Tartare de poisson | D20: =IFERROR(VLOOKUP(C20,ANALYSE!A:F,6,FALSE),0) | E20: =ROUND(PREVISION_SERVICE!D2*D20,1) | F20: portion | G20: Ludovic
A21: =PREVISION_SERVICE!A2 | B21: =PREVISION_SERVICE!C2 | C21: Frites maison | D21: =IFERROR(VLOOKUP(C21,ANALYSE!A:F,6,FALSE),0) | E21: =ROUND(PREVISION_SERVICE!D2*D21,1) | F21: portion | G21: Ludovic
A22: =PREVISION_SERVICE!A2 | B22: =PREVISION_SERVICE!C2 | C22: Salade | D22: =IFERROR(VLOOKUP(C22,ANALYSE!A:F,6,FALSE),0) | E22: =ROUND(PREVISION_SERVICE!D2*D22,1) | F22: portion | G22: Christelle
A23: =PREVISION_SERVICE!A2 | B23: =PREVISION_SERVICE!C2 | C23: Légumes variés | D23: =IFERROR(VLOOKUP(C23,ANALYSE!A:F,6,FALSE),0) | E23: =ROUND(PREVISION_SERVICE!D2*D23,1) | F23: portion | G23: Christelle
A24: =PREVISION_SERVICE!A2 | B24: =PREVISION_SERVICE!C2 | C24: Gratin | D24: =IFERROR(VLOOKUP(C24,ANALYSE!A:F,6,FALSE),0) | E24: =ROUND(PREVISION_SERVICE!D2*D24,1) | F24: portion | G24: Christelle
A25: =PREVISION_SERVICE!A2 | B25: =PREVISION_SERVICE!C2 | C25: Fondant chocolat | D25: =IFERROR(VLOOKUP(C25,ANALYSE!A:F,6,FALSE),0) | E25: =ROUND(PREVISION_SERVICE!D2*D25,1) | F25: portion | G25: Christelle
A26: =PREVISION_SERVICE!A2 | B26: =PREVISION_SERVICE!C2 | C26: Tartelettes | D26: =IFERROR(VLOOKUP(C26,ANALYSE!A:F,6,FALSE),0) | E26: =ROUND(PREVISION_SERVICE!D2*D26,1) | F26: portion | G26: Christelle
A27: =PREVISION_SERVICE!A2 | B27: =PREVISION_SERVICE!C2 | C27: Profiteroles | D27: =IFERROR(VLOOKUP(C27,ANALYSE!A:F,6,FALSE),0) | E27: =ROUND(PREVISION_SERVICE!D2*D27,1) | F27: portion | G27: Christelle
A28: =PREVISION_SERVICE!A2 | B28: =PREVISION_SERVICE!C2 | C28: Gaufres | D28: =IFERROR(VLOOKUP(C28,ANALYSE!A:F,6,FALSE),0) | E28: =ROUND(PREVISION_SERVICE!D2*D28,1) | F28: portion | G28: Christelle
A29: =PREVISION_SERVICE!A2 | B29: =PREVISION_SERVICE!C2 | C29: Compotée | D29: =IFERROR(VLOOKUP(C29,ANALYSE!A:F,6,FALSE),0) | E29: =ROUND(PREVISION_SERVICE!D2*D29,1) | F29: portion | G29: Christelle
A30: =PREVISION_SERVICE!A2 | B30: =PREVISION_SERVICE!C2 | C30: Boule de glace | D30: =IFERROR(VLOOKUP(C30,ANALYSE!A:F,6,FALSE),0) | E30: =ROUND(PREVISION_SERVICE!D2*D30,1) | F30: portion | G30: Christelle
A31: =PREVISION_SERVICE!A3 | B31: =PREVISION_SERVICE!C3 | C31: Accras | D31: =IFERROR(VLOOKUP(C31,ANALYSE!A:F,6,FALSE),0) | E31: =ROUND(PREVISION_SERVICE!D3*D31,1) | F31: portion | G31: Christelle
A32: =PREVISION_SERVICE!A3 | B32: =PREVISION_SERVICE!C3 | C32: Nems | D32: =IFERROR(VLOOKUP(C32,ANALYSE!A:F,6,FALSE),0) | E32: =ROUND(PREVISION_SERVICE!D3*D32,1) | F32: portion | G32: Christelle
A33: =PREVISION_SERVICE!A3 | B33: =PREVISION_SERVICE!C3 | C33: Samoussas | D33: =IFERROR(VLOOKUP(C33,ANALYSE!A:F,6,FALSE),0) | E33: =ROUND(PREVISION_SERVICE!D3*D33,1) | F33: portion | G33: Christelle
A34: =PREVISION_SERVICE!A3 | B34: =PREVISION_SERVICE!C3 | C34: Crevettes tempura | D34: =IFERROR(VLOOKUP(C34,ANALYSE!A:F,6,FALSE),0) | E34: =ROUND(PREVISION_SERVICE!D3*D34,1) | F34: portion | G34: Christelle
A35: =PREVISION_SERVICE!A3 | B35: =PREVISION_SERVICE!C3 | C35: Pisquettes | D35: =IFERROR(VLOOKUP(C35,ANALYSE!A:F,6,FALSE),0) | E35: =ROUND(PREVISION_SERVICE!D3*D35,1) | F35: portion | G35: Christelle
A36: =PREVISION_SERVICE!A3 | B36: =PREVISION_SERVICE!C3 | C36: Tapas trio | D36: =IFERROR(VLOOKUP(C36,ANALYSE!A:F,6,FALSE),0) | E36: =ROUND(PREVISION_SERVICE!D3*D36,1) | F36: portion | G36: Christelle
A37: =PREVISION_SERVICE!A3 | B37: =PREVISION_SERVICE!C3 | C37: Assiette créole | D37: =IFERROR(VLOOKUP(C37,ANALYSE!A:F,6,FALSE),0) | E37: =ROUND(PREVISION_SERVICE!D3*D37,1) | F37: portion | G37: Christelle
A38: =PREVISION_SERVICE!A3 | B38: =PREVISION_SERVICE!C3 | C38: Salade Cap Est | D38: =IFERROR(VLOOKUP(C38,ANALYSE!A:F,6,FALSE),0) | E38: =ROUND(PREVISION_SERVICE!D3*D38,1) | F38: portion | G38: Christelle
A39: =PREVISION_SERVICE!A3 | B39: =PREVISION_SERVICE!C3 | C39: Brochette de boeuf | D39: =IFERROR(VLOOKUP(C39,ANALYSE!A:F,6,FALSE),0) | E39: =ROUND(PREVISION_SERVICE!D3*D39,1) | F39: portion | G39: Ludovic
A40: =PREVISION_SERVICE!A3 | B40: =PREVISION_SERVICE!C3 | C40: Brochette de crevettes | D40: =IFERROR(VLOOKUP(C40,ANALYSE!A:F,6,FALSE),0) | E40: =ROUND(PREVISION_SERVICE!D3*D40,1) | F40: portion | G40: Ludovic
...

Sheet RUPTURES
A1: Horodatage | B1: Date | C1: Service | D1: Employé | E1: Produit | F1: Quantité manquante | G1: Commentaire | H1: Statut achat | I1: Photo

Sheet PERTES
A1: Horodatage | B1: Date | C1: Service | D1: Employé | E1: Produit préparé | F1: Quantité perdue | G1: Motif | H1: Commentaire | I1: Photo justificative

Sheet VALIDATIONS
A1: Horodatage | B1: Date | C1: Service | D1: Employé | E1: Checklist JSON | F1: Remarques | G1: Statut email | H1: Photo contrôle

Sheet STOCK_PRODUITS
A1: Produit | B1: Stock actuel | C1: Stock mini | D1: Fournisseur | E1: Jour conseillé
A2: Morue | B2: 0 | C2: 2 | D2: Poissonnerie | E2: Mardi
A3: Crevettes | B3: 0 | C3: 3 | D3: Poissonnerie | E3: Jeudi
A4: Poisson frais | B4: 0 | C4: 4 | D4: Poissonnerie | E4: Jeudi
A5: Entrecôte | B5: 0 | C5: 6 | D5: Boucherie | E5: Jeudi
A6: Pièce du boucher | B6: 0 | C6: 4 | D6: Boucherie | E6: Jeudi
A7: Magret | B7: 0 | C7: 3 | D7: Boucherie | E7: Jeudi
A8: Côte de boeuf | B8: 0 | C8: 2 | D8: Boucherie | E8: Jeudi
A9: Poulet | B9: 0 | C9: 4 | D9: Boucherie | E9: Jeudi
A10: Pommes de terre | B10: 0 | C10: 8 | D10: Primeur | E10: Mardi
A11: Salade verte | B11: 0 | C11: 4 | D11: Primeur | E11: Mardi
A12: Légumes variés | B12: 0 | C12: 4 | D12: Primeur | E12: Mardi
A13: Desserts | B13: 0 | C13: 4 | D13: Épicerie | E13: Mardi

Sheet COMMANDE_AUTO
A1: Produit | B1: Qté rupture | C1: Qté pertes | D1: Stock actuel | E1: Stock mini | F1: À commander | G1: Fournisseur | H1: Jour conseillé
A2: Morue | B2: =SUMIF(RUPTURES!E:E,A2,RUPTURES!F:F) | C2: =SUMIF(PERTES!E:E,A2,PERTES!F:F) | D2: =IFERROR(VLOOKUP(A2,STOCK_PRODUITS!A:B,2,FALSE),0) | E2: =IFERROR(VLOOKUP(A2,STOCK_PRODUITS!A:C,3,FALSE),0) | F2: =MAX(B2+C2+E2-D2,0) | G2: =IFERROR(VLOOKUP(A2,STOCK_PRODUITS!A:D,4,FALSE),"") | H2: =IFERROR(VLOOKUP(A2,STOCK_PRODUITS!A:E,5,FALSE),"")
A3: Crevettes | B3: =SUMIF(RUPTURES!E:E,A3,RUPTURES!F:F) | C3: =SUMIF(PERTES!E:E,A3,PERTES!F:F) | D3: =IFERROR(VLOOKUP(A3,STOCK_PRODUITS!A:B,2,FALSE),0) | E3: =IFERROR(VLOOKUP(A3,STOCK_PRODUITS!A:C,3,FALSE),0) | F3: =MAX(B3+C3+E3-D3,0) | G3: =IFERROR(VLOOKUP(A3,STOCK_PRODUITS!A:D,4,FALSE),"") | H3: =IFERROR(VLOOKUP(A3,STOCK_PRODUITS!A:E,5,FALSE),"")
A4: Poisson frais | B4: =SUMIF(RUPTURES!E:E,A4,RUPTURES!F:F) | C4: =SUMIF(PERTES!E:E,A4,PERTES!F:F) | D4: =IFERROR(VLOOKUP(A4,STOCK_PRODUITS!A:B,2,FALSE),0) | E4: =IFERROR(VLOOKUP(A4,STOCK_PRODUITS!A:C,3,FALSE),0) | F4: =MAX(B4+C4+E4-D4,0) | G4: =IFERROR(VLOOKUP(A4,STOCK_PRODUITS!A:D,4,FALSE),"") | H4: =IFERROR(VLOOKUP(A4,STOCK_PRODUITS!A:E,5,FALSE),"")
A5: Entrecôte | B5: =SUMIF(RUPTURES!E:E,A5,RUPTURES!F:F) | C5: =SUMIF(PERTES!E:E,A5,PERTES!F:F) | D5: =IFERROR(VLOOKUP(A5,STOCK_PRODUITS!A:B,2,FALSE),0) | E5: =IFERROR(VLOOKUP(A5,STOCK_PRODUITS!A:C,3,FALSE),0) | F5: =MAX(B5+C5+E5-D5,0) | G5: =IFERROR(VLOOKUP(A5,STOCK_PRODUITS!A:D,4,FALSE),"") | H5: =IFERROR(VLOOKUP(A5,STOCK_PRODUITS!A:E,5,FALSE),"")
A6: Pièce du boucher | B6: =SUMIF(RUPTURES!E:E,A6,RUPTURES!F:F) | C6: =SUMIF(PERTES!E:E,A6,PERTES!F:F) | D6: =IFERROR(VLOOKUP(A6,STOCK_PRODUITS!A:B,2,FALSE),0) | E6: =IFERROR(VLOOKUP(A6,STOCK_PRODUITS!A:C,3,FALSE),0) | F6: =MAX(B6+C6+E6-D6,0) | G6: =IFERROR(VLOOKUP(A6,STOCK_PRODUITS!A:D,4,FALSE),"") | H6: =IFERROR(VLOOKUP(A6,STOCK_PRODUITS!A:E,5,FALSE),"")
A7: Magret | B7: =SUMIF(RUPTURES!E:E,A7,RUPTURES!F:F) | C7: =SUMIF(PERTES!E:E,A7,PERTES!F:F) | D7: =IFERROR(VLOOKUP(A7,STOCK_PRODUITS!A:B,2,FALSE),0) | E7: =IFERROR(VLOOKUP(A7,STOCK_PRODUITS!A:C,3,FALSE),0) | F7: =MAX(B7+C7+E7-D7,0) | G7: =IFERROR(VLOOKUP(A7,STOCK_PRODUITS!A:D,4,FALSE),"") | H7: =IFERROR(VLOOKUP(A7,STOCK_PRODUITS!A:E,5,FALSE),"")
A8: Côte de boeuf | B8: =SUMIF(RUPTURES!E:E,A8,RUPTURES!F:F) | C8: =SUMIF(PERTES!E:E,A8,PERTES!F:F) | D8: =IFERROR(VLOOKUP(A8,STOCK_PRODUITS!A:B,2,FALSE),0) | E8: =IFERROR(VLOOKUP(A8,STOCK_PRODUITS!A:C,3,FALSE),0) | F8: =MAX(B8+C8+E8-D8,0) | G8: =IFERROR(VLOOKUP(A8,STOCK_PRODUITS!A:D,4,FALSE),"") | H8: =IFERROR(VLOOKUP(A8,STOCK_PRODUITS!A:E,5,FALSE),"")
A9: Poulet | B9: =SUMIF(RUPTURES!E:E,A9,RUPTURES!F:F) | C9: =SUMIF(PERTES!E:E,A9,PERTES!F:F) | D9: =IFERROR(VLOOKUP(A9,STOCK_PRODUITS!A:B,2,FALSE),0) | E9: =IFERROR(VLOOKUP(A9,STOCK_PRODUITS!A:C,3,FALSE),0) | F9: =MAX(B9+C9+E9-D9,0) | G9: =IFERROR(VLOOKUP(A9,STOCK_PRODUITS!A:D,4,FALSE),"") | H9: =IFERROR(VLOOKUP(A9,STOCK_PRODUITS!A:E,5,FALSE),"")
A10: Pommes de terre | B10: =SUMIF(RUPTURES!E:E,A10,RUPTURES!F:F) | C10: =SUMIF(PERTES!E:E,A10,PERTES!F:F) | D10: =IFERROR(VLOOKUP(A10,STOCK_PRODUITS!A:B,2,FALSE),0) | E10: =IFERROR(VLOOKUP(A10,STOCK_PRODUITS!A:C,3,FALSE),0) | F10: =MAX(B10+C10+E10-D10,0) | G10: =IFERROR(VLOOKUP(A10,STOCK_PRODUITS!A:D,4,FALSE),"") | H10: =IFERROR(VLOOKUP(A10,STOCK_PRODUITS!A:E,5,FALSE),"")
A11: Salade verte | B11: =SUMIF(RUPTURES!E:E,A11,RUPTURES!F:F) | C11: =SUMIF(PERTES!E:E,A11,PERTES!F:F) | D11: =IFERROR(VLOOKUP(A11,STOCK_PRODUITS!A:B,2,FALSE),0) | E11: =IFERROR(VLOOKUP(A11,STOCK_PRODUITS!A:C,3,FALSE),0) | F11: =MAX(B11+C11+E11-D11,0) | G11: =IFERROR(VLOOKUP(A11,STOCK_PRODUITS!A:D,4,FALSE),"") | H11: =IFERROR(VLOOKUP(A11,STOCK_PRODUITS!A:E,5,FALSE),"")
A12: Légumes variés | B12: =SUMIF(RUPTURES!E:E,A12,RUPTURES!F:F) | C12: =SUMIF(PERTES!E:E,A12,PERTES!F:F) | D12: =IFERROR(VLOOKUP(A12,STOCK_PRODUITS!A:B,2,FALSE),0) | E12: =IFERROR(VLOOKUP(A12,STOCK_PRODUITS!A:C,3,FALSE),0) | F12: =MAX(B12+C12+E12-D12,0) | G12: =IFERROR(VLOOKUP(A12,STOCK_PRODUITS!A:D,4,FALSE),"") | H12: =IFERROR(VLOOKUP(A12,STOCK_PRODUITS!A:E,5,FALSE),"")
A13: Desserts | B13: =SUMIF(RUPTURES!E:E,A13,RUPTURES!F:F) | C13: =SUMIF(PERTES!E:E,A13,PERTES!F:F) | D13: =IFERROR(VLOOKUP(A13,STOCK_PRODUITS!A:B,2,FALSE),0) | E13: =IFERROR(VLOOKUP(A13,STOCK_PRODUITS!A:C,3,FALSE),0) | F13: =MAX(B13+C13+E13-D13,0) | G13: =IFERROR(VLOOKUP(A13,STOCK_PRODUITS!A:D,4,FALSE),"") | H13: =IFERROR(VLOOKUP(A13,STOCK_PRODUITS!A:E,5,FALSE),"")

Sheet CHECKLISTS
A1: Employé | B1: Jour | C1: Service | D1: Catégorie | E1: Tâche | F1: Critique | G1: Actif
A2: Christelle | B2: Lundi | C2: Midi | D2: MEP | E2: Vérifier stock froid | F2: Oui | G2: Oui
A3: Christelle | B3: Lundi | C3: Midi | D3: MEP | E3: Préparer accras et entrées froides | F3: Oui | G3: Oui
A4: Christelle | B4: Mardi | C4: Midi | D4: MEP | E4: Contrôler desserts et salades | F4: Oui | G4: Oui
A5: Christelle | B5: Mardi | C5: Soir | D5: MEP | E5: Réassort poste froid | F5: Oui | G5: Oui
A6: Christelle | B6: Mercredi | C6: Midi | D6: Hygiène | E6: Contrôle températures frigos | F6: Oui | G6: Oui
A7: Christelle | B7: Jeudi | C7: Soir | D7: MEP | E7: Préparer mise en place forte affluence | F7: Oui | G7: Oui
A8: Christelle | B8: Vendredi | C8: Midi | D8: MEP | E8: Préparer salades et desserts | F8: Oui | G8: Oui
A9: Christelle | B9: Vendredi | C9: Soir | D9: MEP | E9: Contrôler entrées, desserts et réassort | F9: Oui | G9: Oui
A10: Christelle | B10: Samedi | C10: Soir | D10: MEP | E10: Préparer production maximale poste froid | F10: Oui | G10: Oui
A11: Christelle | B11: Dimanche | C11: Midi | D11: MEP | E11: Optimiser écoulement produits frais | F11: Oui | G11: Oui
A12: Ludovic | B12: Lundi | C12: Midi | D12: MEP | E12: Contrôler viandes et poissons du jour | F12: Oui | G12: Oui
... A25: Lesli | B25: Dimanche | C25: Midi | D25: Nettoyage | E25: Nettoyage fin de service | F25: Oui | G25: Oui

Sheet ADMIN_DASHBOARD
A1: Indicateur | B1: Valeur | D1: Notes admin
A2: Total validations | B2: =COUNTA(VALIDATIONS!A:A)-1 | D2: Renseigner les stocks actuels dans STOCK_PRODUITS.
A3: Total ruptures | B3: =COUNTA(RUPTURES!A:A)-1 | D3: Contrôler COMMANDE_AUTO chaque mardi et jeudi.
A4: Total pertes | B4: =COUNTA(PERTES!A:A)-1 | D4: Les photos sont stockées sous forme de lien ou nom de fichier.
A5: Produits à commander | B5: =COUNTIF(COMMANDE_AUTO!F:F,">0")
A6: Dernière validation | B6: =IFERROR(LOOKUP(2,1/(VALIDATIONS!A:A<>""),VALIDATIONS!A:A),"")
A7: Dernière rupture | B7: =IFERROR(LOOKUP(2,1/(RUPTURES!A:A<>""),RUPTURES!A:A),"")
A8: Dernière perte | B8: =IFERROR(LOOKUP(2,1/(PERTES!A:A<>""),PERTES!A:A),"")

Sheet PHOTOS
A1: Horodatage | B1: Type | C1: Employé | D1: Date | E1: Service | F1: Produit / objet | G1: Lien / nom fichier | H1: Commentaire
